[[mocha-promise]]
== MochaのPromiseサポート

Mochaがサポートしてる"Promiseのテスト"とは何かについて学んでいきましょう。

公式サイトの https://mochajs.org/#asynchronous-code[Asynchronous code]にもその概要が書かれています。

> Alternately, instead of using the done() callback, you can return a promise. This is useful if the APIs you are testing return promises instead of taking callbacks:

Promiseのテストの場合はコールバックとして `done()` を呼ぶ代わりに、promiseオブジェクトをreturnすることができると書いてあります。

では、実際にどのように書くかの例を見ていきたいと思います。


[source,javascript]
[[mocha-promise-test.js]]
.mocha-promise-test.js
----
include::embed/embed-mocha-promise-test.js[]
----

<<promise-assert-fail-fixed,先ほどの `done` を使った例>>をMochaのPromiseテストの形式に変更しました。

変更点としては以下の2つとなっています。

* `done` そのものを取り除いた
* promiseオブジェクトを返すようにした

この書き方をした場合、`assert` が失敗した場合はもちろんテストが失敗します。

[source,javascript]
----
it("should be fail", function () {
    return Promise.resolve().then(function () {
        assert(false);// => テストが失敗する
    });
});
----

これにより `.then(done, done);` というような本質的にはテストとは関係ない記述を省くことができるようになりました。

[NOTE]
====
http://efcl.info/2014/0314/res3708/[MochaがPromisesのテストをサポートしました | Web scratch] という記事でも
MochaのPromiseサポートについて書かれています。
====

=== 意図しないテスト結果

MochaがPromiseのテストをサポートしているため、この書き方でよいと思われるかもしれません。
しかし、この書き方にも意図しない結果になる例外が存在します。

たとえば、以下はある条件だとRejectedなpromiseオブジェクトを返す `mayBeRejected()` のテストコードです。

[source,javascript]
[[mocha-rejected-promise-test]]
.エラーオブジェクトをテストしたい
----
function mayBeRejected(){ // <1>
    return Promise.reject(new Error("woo"));
}
it("is bad pattern", function () {
    return mayBeRejected().catch(function (error) {
        assert(error.message === "woo");
    });
});
----
<1> この関数が返すpromiseオブジェクトをテストしたい


このテストの目的とは以下のようになっています。

`mayBeRejected()` が返すpromiseオブジェクトがFulFilledとなった場合::
    テストを失敗させる
`mayBeRejected()` が返すpromiseオブジェクトがRejectedとなった場合::
    `assert` でErrorオブジェクトをチェックする


上記のテストコードでは、Rejectedとなって `onRejected` に登録された関数が呼ばれるためテストはパスしますね。

このテストで問題になるのは `mayBeRejected()` で返されたpromiseオブジェクトが
**FulFilledとなった場合**に、必ずテストがパスしてしまうという問題が発生します。

[source,javascript]
----
function mayBeRejected(){ // <1>
    return Promise.resolve();
}
it("is bad pattern", function () {
    return mayBeRejected().catch(function (error) {
        assert(error.message === "woo");
    });
});
----
<1> 返されるpromiseオブジェクトはFulFilledとなる

この場合、`catch` で登録した `onRejected` の関数はそもそも呼ばれないため、
`assert` がひとつも呼ばれることなくテストが必ずパスしてしまいます。

これを解消しようとして、`.catch` の前に `.then` を入れて、
`.then` が呼ばれたらテストを失敗にしたいと考えるかもしれません。

[source,javascript]
----
function failTest() { // <1>
    throw new Error("Expected promise to be rejected but it was fulfilled");
}
function mayBeRejected(){
    return Promise.resolve();
}
it("should bad pattern", function () {
    return mayBeRejected().then(failTest).catch(function (error) {
        assert(error.message === "woo");
    });
});
----
<1> throwすることでテストを失敗にしたい

しかし、この書き方だと<<then-or-catch,then or catch?>>で紹介したように、
`failTest` で投げられたエラーが `catch` されてしまいます。

.Then Catch flow
image::../Ch2_HowToWrite/img/then_catch.png[Then Catch flow]

`then` -> `catch` となり、`catch` に渡ってくるErrorオブジェクトは `AssertionError` となり、
意図したものとは違うものが渡ってきてしまいます。

つまり、onRejectedになること**だけ**を期待して書かれたテストは、onFulfilledの状態になってしまうと
常にテストがパスしてしまうという問題を持っていることが分かります。

=== 両状態を明示して意図しないテストを改善

<<mocha-rejected-promise-test,上記のエラーオブジェクトのテスト>>を書く場合、
どのようにすれば意図せず通ってしまうテストを無くすことができるでしょうか?

一番単純な方法としては、以下のようにそれぞれの状態の場合にどうなるのかをテストコードに書く方法です。

FulFilledとなった場合::
    意図したとおりテストが失敗する
Rejectedとなった場合::
    `assert` でテストを行える

つまり、Fulfilled、Rejected 両方の状態について、テストがどうなってほしいかを明示する必要があるわけです。

[source,javascript]
----
function mayBeRejected() {
    return Promise.resolve();
}
it("catch -> then", function () {
    // FulFilledとなった場合はテストは失敗する
    return mayBeRejected().then(failTest, function (error) {
        assert(error.message === "woo");
    });
});
----

このように書くことで、FulFilledとなった場合は失敗するテストコードを書くことができます。

.Promise onRejected test
image::img/promise-test.png[Promise onRejected test]


<<then-or-catch,then or catch?>>のときは、エラーの見逃しを避けるため、
`.then(onFulfilled, onRejected)` の第二引数ではなく、`then` -> `catch` と分けることを推奨していました。

しかし、テストの場合はPromiseの強力なエラーハンドリングが逆にテストの邪魔をしてしまいます。
そのため `.then(failTest, onRejected)` と書くことで、どちらの状態になるのかを明示してテストを書くことができました。


=== まとめ

MochaのPromiseサポートについてと意図しない挙動となる場合について紹介しました。

* 通常のコードは `then` -> `catch` と分けた方がよい
** エラーハンドリングのため。<<then-or-catch,then or catch?>>を参照
* テストコードは `then` にまとめた方がよい
** アサーションエラーがテストフレームワークに届くようにするため。

`.then(onFulfilled, onRejected)` を使うことで、
promiseオブジェクトがFulfilled、Rejectedどちらの状態になるかを明示してテストする必要があります。

しかし、Rejectedのテストであることを明示するために、以下のように書くのはあまり直感的ではないと思います。

[source,javascript]
----
promise.then(failTest, function(error){
    // assertでerrorをテストする
});
----

次は、Promiseのテストを手助けするヘルパー関数を定義して、
もう少し分かりやすいテストを書くにはどうするべきかについて見ていきましょう。
